<?xml version='1.0'?>

<robot name="my_robot" xmlns:xacro="http://www.ros.org/wiki/xacro">

  <link name="robot_footprint"></link>
  <xacro:include filename="$(find my_robot)/urdf/my_robot.gazebo" />

  <joint name="robot_footprint_joint" type="fixed">
    <origin xyz="0 0 0" rpy="0 0 0" />
    <parent link="robot_footprint"/>
    <child link="chassis" />
  </joint>


  <joint name="sensor_holder_joint" type="fixed">
    <origin xyz="0 0 0" rpy="0 0 0" />
    <parent link="chassis"/>
    <child link="sensor_holder" />
  </joint>

  <joint name="hammock_joint" type="fixed">
    <origin xyz="0 0 .1" rpy="0 0 0" />
    <parent link="chassis"/>
    <child link="hammock" />
  </joint>


  <joint name="hammock_top_joint" type="fixed">
    <origin xyz="0 0 0.3" rpy="0 0 0" />
    <parent link="hammock"/>
    <child link="hammock_top" />
  </joint>

  <joint type="continuous" name="left_wheel_hinge">
    <origin xyz="0 0.15 0" rpy="0 0 0"/>
    <child link="left_wheel"/>
    <parent link="chassis"/>
    <axis xyz="0 1 0" rpy="0 0 0"/>
    <limit effort="10000" velocity="1000"/>
    <dynamics damping="1.0" friction="1.0"/>
  </joint>

  <joint type="continuous" name="right_wheel_hinge">
    <origin xyz="0 -0.15 0" rpy="0 0 0"/>
    <child link="right_wheel"/>
    <parent link="chassis"/>
    <axis xyz="0 1 0" rpy="0 0 0"/>
    <limit effort="10000" velocity="1000"/>
    <dynamics damping="1.0" friction="1.0"/>
  </joint>

  <joint type="fixed" name="sensor_joint">
  	<origin xyz="0 0 0.17" rpy="0 0 0"/>
  	<child link="hokuyo"/>
  	<parent link="sensor_holder"/>
  	<axis xyz="0 1 0"/>
  </joint> 

  <joint type="fixed" name="camera_joint">
    <origin xyz="0.06 0 0.1" rpy="0 0 0"/>
    <child link="camera"/>
    <parent link="sensor_holder"/>
    <axis xyz="0 1 0"/>
  </joint> 

  <gazebo reference="left_wheel">
    <material>Gazebo/Orange</material>
  </gazebo>

  <gazebo reference="right_wheel">
    <material>Gazebo/Orange</material>
  </gazebo>

  <gazebo reference="chassis">
    <material>Gazebo/Black</material>
  </gazebo>

  <gazebo reference="hammock">
    <material>Gazebo/Black</material>
  </gazebo>

  <gazebo reference="hammock_top">
    <material>Gazebo/Black</material>
  </gazebo>

  <gazebo reference="sensor_holder">
    <material>Gazebo/Black</material>
  </gazebo>
  <gazebo reference="camera">
    <material>Gazebo/Black</material>
  </gazebo>

  <link name='chassis'>
    <pose>0 0 0.1 0 0 0</pose>

    <inertial>
      <mass value="15.0"/>
      <origin xyz="0.0 0 0" rpy=" 0 0 0"/>
      <inertia
          ixx="0.1" ixy="0" ixz="0"
          iyy="0.1" iyz="0"
          izz="0.1"
      />
    </inertial>

    <collision name='collision'>
      <origin xyz="0 0 0" rpy=" 0 0 0"/> 
      <geometry>
        <box size=".6 .2 .1"/>
      </geometry>
    </collision>

    <visual name='chassis_visual'>
      <origin xyz="0 0 0" rpy=" 0 0 0"/>
      <geometry>
        <box size=".6 .2 .1"/>
      </geometry>
    </visual>


    <collision name='back_caster_collision'>
      <origin xyz="-0.25 0 -0.05" rpy=" 0 0 0"/>
      <geometry>
        <sphere radius="0.03"/>
      </geometry>
    </collision>

    <visual name='back_caster_visual'>
      <origin xyz="-0.25 0 -0.05" rpy=" 0 0 0"/>
      <geometry>
        <sphere radius="0.03"/>
      </geometry>
    </visual>

    <collision name='front_caster_collision'>
      <origin xyz="0.25 0 -0.05" rpy=" 0 0 0"/>
      <geometry>
        <sphere radius="0.03"/>
      </geometry>
    </collision>

    <visual name='front_caster_visual'>
      <origin xyz="0.25 0 -0.05" rpy=" 0 0 0"/>
      <geometry>
        <sphere radius="0.03"/>
      </geometry>
    </visual>

  </link>

  <link name='sensor_holder'>
    <pose>0 0 0.1 0 0 0</pose>

    <inertial>
      <mass value="2.0"/>
      <origin xyz="0.0 0 0.1" rpy=" 0 0 0"/>
      <inertia
          ixx="0.1" ixy="0" ixz="0"
          iyy="0.1" iyz="0"
          izz="0.1"
      />
    </inertial>

    <collision name='sensor_col'>
      <origin xyz="0 0 0.1" rpy=" 0 0 0"/> 
      <geometry>
        <box size=".1 .1 .1"/>
      </geometry>
    </collision>

    <visual name='sensor_vis'>
      <origin xyz="0 0 0.1" rpy=" 0 0 0"/>
      <geometry>
        <box size=".1 .1 .1"/>
      </geometry>
    </visual>

  </link>

  <link name='left_wheel'>
    <inertial>
      <mass value="5.0"/>
      <origin xyz="0.0 0 0" rpy=" 0 1.5707 1.5707"/>
      <inertia
          ixx="0.1" ixy="0" ixz="0"
          iyy="0.1" iyz="0"
          izz="0.1"
      />
    </inertial>

    <collision name='left_wheel_collision'>
      <origin xyz="0.0 0 0" rpy=" 0 1.5707 1.5707"/> 
      <geometry>
        <cylinder length="0.05" radius="0.08"/>
      </geometry>
    </collision>

    <visual name='left_wheel_visual'>
      <origin xyz="0.0 0 0" rpy=" 0 1.5707 1.5707"/>
       <geometry>
        <cylinder length="0.05" radius="0.08"/>
      </geometry>
    </visual>

  </link>

  <link name='right_wheel'>
    <inertial>
      <mass value="5.0"/>
      <origin xyz="0.0 0 0" rpy=" 0 1.5707 1.5707"/>
      <inertia
          ixx="0.1" ixy="0" ixz="0"
          iyy="0.1" iyz="0"
          izz="0.1"
      />
    </inertial>

    <collision name='right_wheel_collision'>
      <origin xyz="0 0 0" rpy=" 0 1.5707 1.5707"/> 
      <geometry>
        <cylinder length="0.05" radius="0.08"/>
      </geometry>
    </collision>

    <visual name='right_wheel_visual'>
      <origin xyz="0.0 0 0" rpy=" 0 1.5707 1.5707"/>
       <geometry>
        <cylinder length="0.05" radius="0.08"/>
      </geometry>
    </visual>

  </link> 

  <link name='camera'>
  	<visual name='camera_vis'>
	    <origin xyz="0 0 0" rpy="0 0 0"/>
	      <geometry>
	      	<box size="0.05 0.05 0.05"/>
	      </geometry>
    </visual>

    <collision name='camera_col'>
    	<origin xyz="0 0 0" rpy="0 0 0"/>
    	<geometry>
    		<box size="0.05 0.05 0.05"/>
    	</geometry>
    </collision>

    <inertial>
    	<mass value="0.1"/>
    	<origin xyz="0 0 0" rpy="0 0 0"/>
    	<inertia 
    	  ixx="1e-6" ixy="0" ixz="0"
          iyy="1e-6" iyz="0"
          izz="1e-6"
    	/>
    </inertial>
  </link>


  


  <link name='hammock'>
    <pose>0 0 0.1 0 0 0</pose>
    <material>Gazebo/Black</material>
    <inertial>
      <mass value="0.1"/>
      <origin xyz="-.25 0 0.1" rpy=" 0 0 0"/>
      <inertia
          ixx="0.1" ixy="0" ixz="0"
          iyy="0.1" iyz="0"
          izz="0.1"
      />
    </inertial>

    <collision name='hammock_col'>
      <origin xyz="-.25 0 0.1" rpy=" 0 0 0"/> 
      <geometry>
        <box size=".1 .1 .35"/>
      </geometry>
    </collision>

    <visual name='hammock_vis'>
      <origin xyz="-.25 0 0.1" rpy=" 0 0 0"/>
      <geometry>
        <box size=".1 .1 .35"/>
      </geometry>
    </visual>

  </link>

  <link name='hammock_top'>
    <pose>0 0 0.1 0 0 0</pose>

    <inertial>
      <mass value="0.1"/>
      <origin xyz="0 0 0" rpy=" 0 0 0"/>
      <inertia
          ixx="0.1" ixy="0" ixz="0"
          iyy="0.1" iyz="0"
          izz="0.1"
      />
    </inertial>

    <collision name='top_col'>
      <origin xyz="0 0 0" rpy=" 0 0 0"/> 
      <geometry>
        <box size=".6 .2 .1"/>
      </geometry>
    </collision>

    <visual name='top_vis'>
      <origin xyz="0 0 0" rpy=" 0 0 0"/>
      <geometry>
        <box size=".6 .2 .1"/>
      </geometry>
    </visual>

  </link>

  <link name="hokuyo">
  	<visual name="sensor_vis">
  		<origin xyz="0 0 0" rpy="0 0 0"/>
  		<geometry>
        <mesh filename="package://my_robot/meshes/hokuyo.dae"/>
      </geometry>
  	</visual>	
  
  	<collision name="sensor_col">
  		<origin xyz="0 0 0" rpy="0 0 0"/>
  		<geometry>
  			<box size="0.1 0.1 0.1"/>
  		</geometry>
  	</collision>

  	<inertial>
    	<mass value="1e-5"/>
    	<origin xyz="0 0 0" rpy="0 0 0"/>
    	<inertia 
    	  ixx="1e-6" ixy="0" ixz="0"
          iyy="1e-6" iyz="0"
          izz="1e-6"
    	/>
    </inertial>

  </link>

  

</robot>
